Workbook

Sheet Dashboard
A1: NBA Draft Value Analysis (2005–2016 First-Round Picks)
A4: Avg Win Shares 23.85 | D4: Avg Games 438.21 | G4: Bust Rate 13.33% | J4: Highest Value Above Expected Chris Paul
C10: Average WS Bar Chart | L10: Draft vs Career WS Scatter Plot
C26: Career Outcomes Pie Chart | L26: Average BPM Bar Chart
C42: Average Games Bar Chart

Sheet DraftData
A1: Year | B1: Pick | C1: Team | D1: Player | E1: College | F1: Games | G1: Minutes | H1: Points | I1: Rebounds | J1: Assists | K1: FG% | L1: 3P% | M1: FT% | N1: Win Shares | O1: WS/48 | P1: BPM | Q1: VORP | R1: MPG | S1: PPG | T1: RPG | U1: APG | V1: Pick Range | W1: Career Tier | X1: Bust? | Y1: Pick Efficiency | Z1: Value Above Expected
A2: 2005 | B2: 1 | C2: MIL | D2: Andrew Bogut | E2: Utah | F2: 706 | G2: 19862 | H2: 6808 | I2: 6112 | J2: 1546 | K2: 0.535 | L2: 0.12 | M2: 0.557 | N2: 50.6 | O2: 0.122 | P2: 1.2 | Q2: 16 | R2: 28.1 | S2: 9.6 | T2: 8.7 | U2: 2.2 | V2: =IF(DraftData[[#This Row],[Pick]]<=5,"Top 5", IF(DraftData[[#This Row],[Pick]]<=14,"Lottery", IF(DraftData[[#This Row],[Pick]]<=20,"Mid First","Late First"))) -> Top 5 | W2: =IF(DraftData[[#This Row],[Win Shares]]>=80,"Star", IF(DraftData[[#This Row],[Win Shares]]>=30,"Starter", IF(DraftData[[#This Row],[Win Shares]]>=10,"Rotation","Minimal"))) -> Starter | X2: =IF(AND(DraftData[[#This Row],[Pick]]<=14,DraftData[[#This Row],[Win Shares]]<10),"Yes","No") -> No | Y2: =DraftData[[#This Row],[Win Shares]]/DraftData[[#This Row],[Pick]] -> 50.6 | Z2: =DraftData[[#This Row],[Win Shares]]-_xlfn.XLOOKUP(DraftData[[#This Row],[Pick]],'Lookup Tables'!$A$2:$A$31,'Lookup Tables'!$B$2:$B$31) -> 7.0166667
A3: 2005 | B3: 2 | C3: ATL | D3: Marvin Williams | E3: UNC | F3: 1072 | G3: 30159 | H3: 10965 | I3: 5546 | J3: 1373 | K3: 0.443 | L3: 0.361 | M3: 0.808 | N3: 65.1 | O3: 0.104 | P3: -0.4 | Q3: 12.3 | R3: 28.1 | S3: 10.2 | T3: 5.2 | U3: 1.3 | V3: =IF(DraftData[[#This Row],[Pick]]<=5,"Top 5", IF(DraftData[[#This Row],[Pick]]<=14,"Lottery", IF(DraftData[[#This Row],[Pick]]<=20,"Mid First","Late First"))) -> Top 5 | W3: =IF(DraftData[[#This Row],[Win Shares]]>=80,"Star", IF(DraftData[[#This Row],[Win Shares]]>=30,"Starter", IF(DraftData[[#This Row],[Win Shares]]>=10,"Rotation","Minimal"))) -> Starter | X3: =IF(AND(DraftData[[#This Row],[Pick]]<=14,DraftData[[#This Row],[Win Shares]]<10),"Yes","No") -> No | Y3: =DraftData[[#This Row],[Win Shares]]/DraftData[[#This Row],[Pick]] -> 32.55 | Z3: =DraftData[[#This Row],[Win Shares]]-_xlfn.XLOOKUP(DraftData[[#This Row],[Pick]],'Lookup Tables'!$A$2:$A$31,'Lookup Tables'!$B$2:$B$31) -> 25.308333
A4: 2005 | B4: 3 | C4: UTA | D4: Deron Williams | E4: Illinois | F4: 845 | G4: 28865 | H4: 13804 | I4: 2619 | J4: 6819 | K4: 0.445 | L4: 0.357 | M4: 0.822 | N4: 77.3 | O4: 0.129 | P4: 1.9 | Q4: 28.3 | R4: 34.2 | S4: 16.3 | T4: 3.1 | U4: 8.1 | V4: =IF(DraftData[[#This Row],[Pick]]<=5,"Top 5", IF(DraftData[[#This Row],[Pick]]<=14,"Lottery", IF(DraftData[[#This Row],[Pick]]<=20,"Mid First","Late First"))) -> Top 5 | W4: =IF(DraftData[[#This Row],[Win Shares]]>=80,"Star", IF(DraftData[[#This Row],[Win Shares]]>=30,"Starter", IF(DraftData[[#This Row],[Win Shares]]>=10,"Rotation","Minimal"))) -> Starter | X4: =IF(AND(DraftData[[#This Row],[Pick]]<=14,DraftData[[#This Row],[Win Shares]]<10),"Yes","No") -> No | Y4: =DraftData[[#This Row],[Win Shares]]/DraftData[[#This Row],[Pick]] -> 25.766667 | Z4: =DraftData[[#This Row],[Win Shares]]-_xlfn.XLOOKUP(DraftData[[#This Row],[Pick]],'Lookup Tables'!$A$2:$A$31,'Lookup Tables'!$B$2:$B$31) -> 26.533333
A5: 2005 | B5: 4 | C5: NOP | D5: Chris Paul | E5: Wake Forest | F5: 1148 | G5: 39673 | H5: 20844 | I5: 5182 | J5: 10894 | K5: 0.473 | L5: 0.37 | M5: 0.872 | N5: 198.2 | O5: 0.24 | P5: 7.3 | Q5: 93.2 | R5: 34.6 | S5: 18.2 | T5: 4.5 | U5: 9.5 | V5: =IF(DraftData[[#This Row],[Pick]]<=5,"Top 5", IF(DraftData[[#This Row],[Pick]]<=14,"Lottery", IF(DraftData[[#This Row],[Pick]]<=20,"Mid First","Late First"))) -> Top 5 | W5: =IF(DraftData[[#This Row],[Win Shares]]>=80,"Star", IF(DraftData[[#This Row],[Win Shares]]>=30,"Starter", IF(DraftData[[#This Row],[Win Shares]]>=10,"Rotation","Minimal"))) -> Star | X5: =IF(AND(DraftData[[#This Row],[Pick]]<=14,DraftData[[#This Row],[Win Shares]]<10),"Yes","No") -> No | Y5: =DraftData[[#This Row],[Win Shares]]/DraftData[[#This Row],[Pick]] -> 49.55 | Z5: =DraftData[[#This Row],[Win Shares]]-_xlfn.XLOOKUP(DraftData[[#This Row],[Pick]],'Lookup Tables'!$A$2:$A$31,'Lookup Tables'!$B$2:$B$31) -> 149.64167
A6: 2005 | B6: 5 | C6: CHA | D6: Raymond Felton | E6: UNC | F6: 971 | G6: 28829 | H6: 10853 | I6: 2867 | J6: 5096 | K6: 0.412 | L6: 0.329 | M6: 0.79 | N6: 40.2 | O6: 0.067 | P6: -0.6 | Q6: 10.1 | R6: 29.7 | S6: 11.2 | T6: 3 | U6: 5.2 | V6: =IF(DraftData[[#This Row],[Pick]]<=5,"Top 5", IF(DraftData[[#This Row],[Pick]]<=14,"Lottery", IF(DraftData[[#This Row],[Pick]]<=20,"Mid First","Late First"))) -> Top 5 | W6: =IF(DraftData[[#This Row],[Win Shares]]>=80,"Star", IF(DraftData[[#This Row],[Win Shares]]>=30,"Starter", IF(DraftData[[#This Row],[Win Shares]]>=10,"Rotation","Minimal"))) -> Starter | X6: =IF(AND(DraftData[[#This Row],[Pick]]<=14,DraftData[[#This Row],[Win Shares]]<10),"Yes","No") -> No | Y6: =DraftData[[#This Row],[Win Shares]]/DraftData[[#This Row],[Pick]] -> 8.04 | Z6: =DraftData[[#This Row],[Win Shares]]-_xlfn.XLOOKUP(DraftData[[#This Row],[Pick]],'Lookup Tables'!$A$2:$A$31,'Lookup Tables'!$B$2:$B$31) -> 8.8416667
A7: 2005 | B7: 6 | C7: POR | D7: Martell Webster | F7: 580 | G7: 13914 | H7: 5056 | I7: 1811 | J7: 588 | K7: 0.418 | L7: 0.382 | M7: 0.791 | N7: 24.7 | O7: 0.085 | P7: -0.8 | Q7: 4.3 | R7: 24 | S7: 8.7 | T7: 3.1 | U7: 1 | V7: =IF(DraftData[[#This Row],[Pick]]<=5,"Top 5", IF(DraftData[[#This Row],[Pick]]<=14,"Lottery", IF(DraftData[[#This Row],[Pick]]<=20,"Mid First","Late First"))) -> Lottery | W7: =IF(DraftData[[#This Row],[Win Shares]]>=80,"Star", IF(DraftData[[#This Row],[Win Shares]]>=30,"Starter", IF(DraftData[[#This Row],[Win Shares]]>=10,"Rotation","Minimal"))) -> Rotation | X7: =IF(AND(DraftData[[#This Row],[Pick]]<=14,DraftData[[#This Row],[Win Shares]]<10),"Yes","No") -> No | Y7: =DraftData[[#This Row],[Win Shares]]/DraftData[[#This Row],[Pick]] -> 4.1166667 | Z7: =DraftData[[#This Row],[Win Shares]]-_xlfn.XLOOKUP(DraftData[[#This Row],[Pick]],'Lookup Tables'!$A$2:$A$31,'Lookup Tables'!$B$2:$B$31) -> -2.9583333
A8: 2005 | B8: 7 | C8: TOR | D8: Charlie Villanueva | E8: UConn | F8: 656 | G8: 13578 | H8: 6808 | I8: 3019 | J8: 549 | K8: 0.435 | L8: 0.341 | M8: 0.772 | N8: 22.6 | O8: 0.08 | P8: -0.6 | Q8: 4.7 | R8: 20.7 | S8: 10.4 | T8: 4.6 | U8: 0.8 | V8: =IF(DraftData[[#This Row],[Pick]]<=5,"Top 5", IF(DraftData[[#This Row],[Pick]]<=14,"Lottery", IF(DraftData[[#This Row],[Pick]]<=20,"Mid First","Late First"))) -> Lottery | W8: =IF(DraftData[[#This Row],[Win Shares]]>=80,"Star", IF(DraftData[[#This Row],[Win Shares]]>=30,"Starter", IF(DraftData[[#This Row],[Win Shares]]>=10,"Rotation","Minimal"))) -> Rotation | X8: =IF(AND(DraftData[[#This Row],[Pick]]<=14,DraftData[[#This Row],[Win Shares]]<10),"Yes","No") -> No | Y8: =DraftData[[#This Row],[Win Shares]]/DraftData[[#This Row],[Pick]] -> 3.2285714 | Z8: =DraftData[[#This Row],[Win Shares]]-_xlfn.XLOOKUP(DraftData[[#This Row],[Pick]],'Lookup Tables'!$A$2:$A$31,'Lookup Tables'!$B$2:$B$31) -> -11.375
A9: 2005 | B9: 8 | C9: NYK | D9: Channing Frye | E9: Arizona | F9: 890 | G9: 19772 | H9: 7786 | I9: 4002 | J9: 864 | K9: 0.44 | L9: 0.388 | M9: 0.822 | N9: 38.9 | O9: 0.094 | P9: -0.4 | Q9: 8 | R9: 22.2 | S9: 8.7 | T9: 4.5 | U9: 1 | V9: =IF(DraftData[[#This Row],[Pick]]<=5,"Top 5", IF(DraftData[[#This Row],[Pick]]<=14,"Lottery", IF(DraftData[[#This Row],[Pick]]<=20,"Mid First","Late First"))) -> Lottery | W9: =IF(DraftData[[#This Row],[Win Shares]]>=80,"Star", IF(DraftData[[#This Row],[Win Shares]]>=30,"Starter", IF(DraftData[[#This Row],[Win Shares]]>=10,"Rotation","Minimal"))) -> Starter | X9: =IF(AND(DraftData[[#This Row],[Pick]]<=14,DraftData[[#This Row],[Win Shares]]<10),"Yes","No") -> No | Y9: =DraftData[[#This Row],[Win Shares]]/DraftData[[#This Row],[Pick]] -> 4.8625 | Z9: =DraftData[[#This Row],[Win Shares]]-_xlfn.XLOOKUP(DraftData[[#This Row],[Pick]],'Lookup Tables'!$A$2:$A$31,'Lookup Tables'!$B$2:$B$31) -> 17.741667
A10: 2005 | B10: 9 | C10: GSW | D10: Ike Diogu | E10: Arizona State | F10: 225 | G10: 2795 | H10: 1348 | I10: 689 | J10: 69 | K10: 0.509 | L10: 0.5 | M10: 0.786 | N10: 6.5 | O10: 0.112 | P10: -3 | Q10: -0.7 | R10: 12.4 | S10: 6 | T10: 3.1 | U10: 0.3 | V10: =IF(DraftData[[#This Row],[Pick]]<=5,"Top 5", IF(DraftData[[#This Row],[Pick]]<=14,"Lottery", IF(DraftData[[#This Row],[Pick]]<=20,"Mid First","Late First"))) -> Lottery | W10: =IF(DraftData[[#This Row],[Win Shares]]>=80,"Star", IF(DraftData[[#This Row],[Win Shares]]>=30,"Starter", IF(DraftData[[#This Row],[Win Shares]]>=10,"Rotation","Minimal"))) -> Minimal | X10: =IF(AND(DraftData[[#This Row],[Pick]]<=14,DraftData[[#This Row],[Win Shares]]<10),"Yes","No") -> Yes | Y10: =DraftData[[#This Row],[Win Shares]]/DraftData[[#This Row],[Pick]] -> 0.72222222 | Z10: =DraftData[[#This Row],[Win Shares]]-_xlfn.XLOOKUP(DraftData[[#This Row],[Pick]],'Lookup Tables'!$A$2:$A$31,'Lookup Tables'!$B$2:$B$31) -> -30.891667
A11: 2005 | B11: 10 | C11: LAL | D11: Andrew Bynum | F11: 418 | G11: 10690 | H11: 4822 | I11: 3221 | J11: 490 | K11: 0.556 | L11: 0.111 | M11: 0.69 | N11: 37.4 | O11: 0.168 | P11: 1.4 | Q11: 9.1 | R11: 25.6 | S11: 11.5 | T11: 7.7 | U11: 1.2 | V11: =IF(DraftData[[#This Row],[Pick]]<=5,"Top 5", IF(DraftData[[#This Row],[Pick]]<=14,"Lottery", IF(DraftData[[#This Row],[Pick]]<=20,"Mid First","Late First"))) -> Lottery | W11: =IF(DraftData[[#This Row],[Win Shares]]>=80,"Star", IF(DraftData[[#This Row],[Win Shares]]>=30,"Starter", IF(DraftData[[#This Row],[Win Shares]]>=10,"Rotation","Minimal"))) -> Starter | X11: =IF(AND(DraftData[[#This Row],[Pick]]<=14,DraftData[[#This Row],[Win Shares]]<10),"Yes","No") -> No | Y11: =DraftData[[#This Row],[Win Shares]]/DraftData[[#This Row],[Pick]] -> 3.74 | Z11: =DraftData[[#This Row],[Win Shares]]-_xlfn.XLOOKUP(DraftData[[#This Row],[Pick]],'Lookup Tables'!$A$2:$A$31,'Lookup Tables'!$B$2:$B$31) -> 10.55
A12: 2005 | B12: 11 | C12: ORL | D12: Fran Vázquez | V12: =IF(DraftData[[#This Row],[Pick]]<=5,"Top 5", IF(DraftData[[#This Row],[Pick]]<=14,"Lottery", IF(DraftData[[#This Row],[Pick]]<=20,"Mid First","Late First"))) -> Lottery | W12: =IF(DraftData[[#This Row],[Win Shares]]>=80,"Star", IF(DraftData[[#This Row],[Win Shares]]>=30,"Starter", IF(DraftData[[#This Row],[Win Shares]]>=10,"Rotation","Minimal"))) -> Minimal | X12: =IF(AND(DraftData[[#This Row],[Pick]]<=14,DraftData[[#This Row],[Win Shares]]<10),"Yes","No") -> Yes | Y12: =DraftData[[#This Row],[Win Shares]]/DraftData[[#This Row],[Pick]] -> 0 | Z12: =DraftData[[#This Row],[Win Shares]]-_xlfn.XLOOKUP(DraftData[[#This Row],[Pick]],'Lookup Tables'!$A$2:$A$31,'Lookup Tables'!$B$2:$B$31) -> -22.7
A13: 2005 | B13: 12 | C13: LAC | D13: Yaroslav Korolev | F13: 34 | G13: 168 | H13: 39 | I13: 16 | J13: 13 | K13: 0.283 | L13: 0.25 | M13: 0.625 | N13: -0.1 | O13: -0.024 | P13: -5.2 | Q13: -0.1 | R13: 4.9 | S13: 1.1 | T13: 0.5 | U13: 0.4 | V13: =IF(DraftData[[#This Row],[Pick]]<=5,"Top 5", IF(DraftData[[#This Row],[Pick]]<=14,"Lottery", IF(DraftData[[#This Row],[Pick]]<=20,"Mid First","Late First"))) -> Lottery | W13: =IF(DraftData[[#This Row],[Win Shares]]>=80,"Star", IF(DraftData[[#This Row],[Win Shares]]>=30,"Starter", IF(DraftData[[#This Row],[Win Shares]]>=10,"Rotation","Minimal"))) -> Minimal | X13: =IF(AND(DraftData[[#This Row],[Pick]]<=14,DraftData[[#This Row],[Win Shares]]<10),"Yes","No") -> Yes | Y13: =DraftData[[#This Row],[Win Shares]]/DraftData[[#This Row],[Pick]] -> -0.0083333333 | Z13: =DraftData[[#This Row],[Win Shares]]-_xlfn.XLOOKUP(DraftData[[#This Row],[Pick]],'Lookup Tables'!$A$2:$A$31,'Lookup Tables'!$B$2:$B$31) -> -21.416667
A14: 2005 | B14: 13 | C14: CHA | D14: Sean May | E14: UNC | F14: 119 | G14: 1868 | H14: 821 | I14: 481 | J14: 115 | K14: 0.458 | L14: 0.231 | M14: 0.746 | N14: 2.6 | O14: 0.068 | P14: -1.7 | Q14: 0.2 | R14: 15.7 | S14: 6.9 | T14: 4 | U14: 1 | V14: =IF(DraftData[[#This Row],[Pick]]<=5,"Top 5", IF(DraftData[[#This Row],[Pick]]<=14,"Lottery", IF(DraftData[[#This Row],[Pick]]<=20,"Mid First","Late First"))) -> Lottery | W14: =IF(DraftData[[#This Row],[Win Shares]]>=80,"Star", IF(DraftData[[#This Row],[Win Shares]]>=30,"Starter", IF(DraftData[[#This Row],[Win Shares]]>=10,"Rotation","Minimal"))) -> Minimal | X14: =IF(AND(DraftData[[#This Row],[Pick]]<=14,DraftData[[#This Row],[Win Shares]]<10),"Yes","No") -> Yes | Y14: =DraftData[[#This Row],[Win Shares]]/DraftData[[#This Row],[Pick]] -> 0.2 | Z14: =DraftData[[#This Row],[Win Shares]]-_xlfn.XLOOKUP(DraftData[[#This Row],[Pick]],'Lookup Tables'!$A$2:$A$31,'Lookup Tables'!$B$2:$B$31) -> -16.733333
A15: 2005 | B15: 14 | C15: MIN | D15: Rashad McCants | E15: UNC | F15: 249 | G15: 5037 | H15: 2479 | I15: 506 | J15: 331 | K15: 0.431 | L15: 0.368 | M15: 0.741 | N15: 3.6 | O15: 0.035 | P15: -1.7 | Q15: 0.4 | R15: 20.2 | S15: 10 | T15: 2 | U15: 1.3 | V15: =IF(DraftData[[#This Row],[Pick]]<=5,"Top 5", IF(DraftData[[#This Row],[Pick]]<=14,"Lottery", IF(DraftData[[#This Row],[Pick]]<=20,"Mid First","Late First"))) -> Lottery | W15: =IF(DraftData[[#This Row],[Win Shares]]>=80,"Star", IF(DraftData[[#This Row],[Win Shares]]>=30,"Starter", IF(DraftData[[#This Row],[Win Shares]]>=10,"Rotation","Minimal"))) -> Minimal | X15: =IF(AND(DraftData[[#This Row],[Pick]]<=14,DraftData[[#This Row],[Win Shares]]<10),"Yes","No") -> Yes | Y15: =DraftData[[#This Row],[Win Shares]]/DraftData[[#This Row],[Pick]] -> 0.25714286 | Z15: =DraftData[[#This Row],[Win Shares]]-_xlfn.XLOOKUP(DraftData[[#This Row],[Pick]],'Lookup Tables'!$A$2:$A$31,'Lookup Tables'!$B$2:$B$31) -> -11.15
A16: 2005 | B16: 15 | C16: BRK | D16: Antoine Wright | E16: Texas A&M | F16: 297 | G16: 5714 | H16: 1614 | I16: 681 | J16: 295 | K16: 0.412 | L16: 0.304 | M16: 0.674 | N16: 3.1 | O16: 0.026 | P16: -3.7 | Q16: -2.4 | R16: 19.2 | S16: 5.4 | T16: 2.3 | U16: 1 | V16: =IF(DraftData[[#This Row],[Pick]]<=5,"Top 5", IF(DraftData[[#This Row],[Pick]]<=14,"Lottery", IF(DraftData[[#This Row],[Pick]]<=20,"Mid First","Late First"))) -> Mid First | W16: =IF(DraftData[[#This Row],[Win Shares]]>=80,"Star", IF(DraftData[[#This Row],[Win Shares]]>=30,"Starter", IF(DraftData[[#This Row],[Win Shares]]>=10,"Rotation","Minimal"))) -> Minimal | X16: =IF(AND(DraftData[[#This Row],[Pick]]<=14,DraftData[[#This Row],[Win Shares]]<10),"Yes","No") -> No | Y16: =DraftData[[#This Row],[Win Shares]]/DraftData[[#This Row],[Pick]] -> 0.20666667 | Z16: =DraftData[[#This Row],[Win Shares]]-_xlfn.XLOOKUP(DraftData[[#This Row],[Pick]],'Lookup Tables'!$A$2:$A$31,'Lookup Tables'!$B$2:$B$31) -> -22.683333
A17: 2005 | B17: 16 | C17: TOR | D17: Joey Graham | E17: Oklahoma State | F17: 377 | G17: 6117 | H17: 2239 | I17: 1058 | J17: 207 | K17: 0.483 | L17: 0.3 | M17: 0.815 | N17: 7.8 | O17: 0.061 | P17: -3.6 | Q17: -2.4 | R17: 16.2 | S17: 5.9 | T17: 2.8 | U17: 0.5 | V17: =IF(DraftData[[#This Row],[Pick]]<=5,"Top 5", IF(DraftData[[#This Row],[Pick]]<=14,"Lottery", IF(DraftData[[#This Row],[Pick]]<=20,"Mid First","Late First"))) -> Mid First | W17: =IF(DraftData[[#This Row],[Win Shares]]>=80,"Star", IF(DraftData[[#This Row],[Win Shares]]>=30,"Starter", IF(DraftData[[#This Row],[Win Shares]]>=10,"Rotation","Minimal"))) -> Minimal | X17: =IF(AND(DraftData[[#This Row],[Pick]]<=14,DraftData[[#This Row],[Win Shares]]<10),"Yes","No") -> No | Y17: =DraftData[[#This Row],[Win Shares]]/DraftData[[#This Row],[Pick]] -> 0.4875 | Z17: =DraftData[[#This Row],[Win Shares]]-_xlfn.XLOOKUP(DraftData[[#This Row],[Pick]],'Lookup Tables'!$A$2:$A$31,'Lookup Tables'!$B$2:$B$31) -> -9.1833333
A18: 2005 | B18: 17 | C18: IND | D18: Danny Granger | E18: New Mexico | F18: 586 | G18: 18487 | H18: 9855 | I18: 2888 | J18: 1097 | K18: 0.434 | L18: 0.38 | M18: 0.848 | N18: 48.5 | O18: 0.126 | P18: 1.8 | Q18: 17.7 | R18: 31.5 | S18: 16.8 | T18: 4.9 | U18: 1.9 | V18: =IF(DraftData[[#This Row],[Pick]]<=5,"Top 5", IF(DraftData[[#This Row],[Pick]]<=14,"Lottery", IF(DraftData[[#This Row],[Pick]]<=20,"Mid First","Late First"))) -> Mid First | W18: =IF(DraftData[[#This Row],[Win Shares]]>=80,"Star", IF(DraftData[[#This Row],[Win Shares]]>=30,"Starter", IF(DraftData[[#This Row],[Win Shares]]>=10,"Rotation","Minimal"))) -> Starter | X18: =IF(AND(DraftData[[#This Row],[Pick]]<=14,DraftData[[#This Row],[Win Shares]]<10),"Yes","No") -> No | Y18: =DraftData[[#This Row],[Win Shares]]/DraftData[[#This Row],[Pick]] -> 2.8529412 | Z18: =DraftData[[#This Row],[Win Shares]]-_xlfn.XLOOKUP(DraftData[[#This Row],[Pick]],'Lookup Tables'!$A$2:$A$31,'Lookup Tables'!$B$2:$B$31) -> 31.183333
A19: 2005 | B19: 18 | C19: BOS | D19: Gerald Green | F19: 658 | G19: 13026 | H19: 6412 | I19: 1639 | J19: 596 | K19: 0.417 | L19: 0.361 | M19: 0.818 | N19: 18.4 | O19: 0.068 | P19: -1.3 | Q19: 2.4 | R19: 19.8 | S19: 9.7 | T19: 2.5 | U19: 0.9 | V19: =IF(DraftData[[#This Row],[Pick]]<=5,"Top 5", IF(DraftData[[#This Row],[Pick]]<=14,"Lottery", IF(DraftData[[#This Row],[Pick]]<=20,"Mid First","Late First"))) -> Mid First | W19: =IF(DraftData[[#This Row],[Win Shares]]>=80,"Star", IF(DraftData[[#This Row],[Win Shares]]>=30,"Starter", IF(DraftData[[#This Row],[Win Shares]]>=10,"Rotation","Minimal"))) -> Rotation | X19: =IF(AND(DraftData[[#This Row],[Pick]]<=14,DraftData[[#This Row],[Win Shares]]<10),"Yes","No") -> No | Y19: =DraftData[[#This Row],[Win Shares]]/DraftData[[#This Row],[Pick]] -> 1.0222222 | Z19: =DraftData[[#This Row],[Win Shares]]-_xlfn.XLOOKUP(DraftData[[#This Row],[Pick]],'Lookup Tables'!$A$2:$A$31,'Lookup Tables'!$B$2:$B$31) -> 1.0916667
A20: 2005 | B20: 19 | C20: MEM | D20: Hakim Warrick | E20: Syracuse | F20: 526 | G20: 10624 | H20: 4947 | I20: 2117 | J20: 400 | K20: 0.49 | L20: 0.191 | M20: 0.726 | N20: 20.4 | O20: 0.092 | P20: -1.9 | Q20: 0.4 | R20: 20.2 | S20: 9.4 | T20: 4 | U20: 0.8 | V20: =IF(DraftData[[#This Row],[Pick]]<=5,"Top 5", IF(DraftData[[#This Row],[Pick]]<=14,"Lottery", IF(DraftData[[#This Row],[Pick]]<=20,"Mid First","Late First"))) -> Mid First | W20: =IF(DraftData[[#This Row],[Win Shares]]>=80,"Star", IF(DraftData[[#This Row],[Win Shares]]>=30,"Starter", IF(DraftData[[#This Row],[Win Shares]]>=10,"Rotation","Minimal"))) -> Rotation | X20: =IF(AND(DraftData[[#This Row],[Pick]]<=14,DraftData[[#This Row],[Win Shares]]<10),"Yes","No") -> No | Y20: =DraftData[[#This Row],[Win Shares]]/DraftData[[#This Row],[Pick]] -> 1.0736842 | Z20: =DraftData[[#This Row],[Win Shares]]-_xlfn.XLOOKUP(DraftData[[#This Row],[Pick]],'Lookup Tables'!$A$2:$A$31,'Lookup Tables'!$B$2:$B$31) -> 2.825
A21: 2005 | B21: 20 | C21: DEN | D21: Julius Hodge | E21: NC State | F21: 23 | G21: 98 | H21: 28 | I21: 15 | J21: 18 | K21: 0.44 | M21: 0.5 | N21: 0 | O21: 0.003 | P21: -3.7 | Q21: 0 | R21: 4.3 | S21: 1.2 | T21: 0.7 | U21: 0.8 | V21: =IF(DraftData[[#This Row],[Pick]]<=5,"Top 5", IF(DraftData[[#This Row],[Pick]]<=14,"Lottery", IF(DraftData[[#This Row],[Pick]]<=20,"Mid First","Late First"))) -> Mid First | W21: =IF(DraftData[[#This Row],[Win Shares]]>=80,"Star", IF(DraftData[[#This Row],[Win Shares]]>=30,"Starter", IF(DraftData[[#This Row],[Win Shares]]>=10,"Rotation","Minimal"))) -> Minimal | X21: =IF(AND(DraftData[[#This Row],[Pick]]<=14,DraftData[[#This Row],[Win Shares]]<10),"Yes","No") -> No | Y21: =DraftData[[#This Row],[Win Shares]]/DraftData[[#This Row],[Pick]] -> 0 | Z21: =DraftData[[#This Row],[Win Shares]]-_xlfn.XLOOKUP(DraftData[[#This Row],[Pick]],'Lookup Tables'!$A$2:$A$31,'Lookup Tables'!$B$2:$B$31) -> -10.391667
A22: 2005 | B22: 21 | C22: PHO | D22: Nate Robinson | E22: Washington | F22: 618 | G22: 13878 | H22: 6807 | I22: 1446 | J22: 1826 | K22: 0.423 | L22: 0.36 | M22: 0.796 | N22: 27.8 | O22: 0.096 | P22: 0.5 | Q22: 8.6 | R22: 22.5 | S22: 11 | T22: 2.3 | U22: 3 | V22: =IF(DraftData[[#This Row],[Pick]]<=5,"Top 5", IF(DraftData[[#This Row],[Pick]]<=14,"Lottery", IF(DraftData[[#This Row],[Pick]]<=20,"Mid First","Late First"))) -> Late First | W22: =IF(DraftData[[#This Row],[Win Shares]]>=80,"Star", IF(DraftData[[#This Row],[Win Shares]]>=30,"Starter", IF(DraftData[[#This Row],[Win Shares]]>=10,"Rotation","Minimal"))) -> Rotation | X22: =IF(AND(DraftData[[#This Row],[Pick]]<=14,DraftData[[#This Row],[Win Shares]]<10),"Yes","No") -> No | Y22: =DraftData[[#This Row],[Win Shares]]/DraftData[[#This Row],[Pick]] -> 1.3238095 | Z22: =DraftData[[#This Row],[Win Shares]]-_xlfn.XLOOKUP(DraftData[[#This Row],[Pick]],'Lookup Tables'!$A$2:$A$31,'Lookup Tables'!$B$2:$B$31) -> 7.3
A23: 2005 | B23: 22 | C23: DEN | D23: Jarrett Jack | E23: Georgia Tech | F23: 867 | G23: 24140 | H23: 9349 | I23: 2487 | J23: 3952 | K23: 0.44 | L23: 0.343 | M23: 0.855 | N23: 36.8 | O23: 0.073 | P23: -0.9 | Q23: 6.5 | R23: 27.8 | S23: 10.8 | T23: 2.9 | U23: 4.6 | V23: =IF(DraftData[[#This Row],[Pick]]<=5,"Top 5", IF(DraftData[[#This Row],[Pick]]<=14,"Lottery", IF(DraftData[[#This Row],[Pick]]<=20,"Mid First","Late First"))) -> Late First | W23: =IF(DraftData[[#This Row],[Win Shares]]>=80,"Star", IF(DraftData[[#This Row],[Win Shares]]>=30,"Starter", IF(DraftData[[#This Row],[Win Shares]]>=10,"Rotation","Minimal"))) -> Starter | X23: =IF(AND(DraftData[[#This Row],[Pick]]<=14,DraftData[[#This Row],[Win Shares]]<10),"Yes","No") -> No | Y23: =DraftData[[#This Row],[Win Shares]]/DraftData[[#This Row],[Pick]] -> 1.6727273 | Z23: =DraftData[[#This Row],[Win Shares]]-_xlfn.XLOOKUP(DraftData[[#This Row],[Pick]],'Lookup Tables'!$A$2:$A$31,'Lookup Tables'!$B$2:$B$31) -> 18.316667
A24: 2005 | B24: 23 | C24: SAC | D24: Francisco García | E24: Louisville | F24: 549 | G24: 11853 | H24: 4323 | I24: 1400 | J24: 747 | K24: 0.427 | L24: 0.357 | M24: 0.799 | N24: 18.2 | O24: 0.074 | P24: -0.1 | Q24: 5.7 | R24: 21.6 | S24: 7.9 | T24: 2.6 | U24: 1.4 | V24: =IF(DraftData[[#This Row],[Pick]]<=5,"Top 5", IF(DraftData[[#This Row],[Pick]]<=14,"Lottery", IF(DraftData[[#This Row],[Pick]]<=20,"Mid First","Late First"))) -> Late First | W24: =IF(DraftData[[#This Row],[Win Shares]]>=80,"Star", IF(DraftData[[#This Row],[Win Shares]]>=30,"Starter", IF(DraftData[[#This Row],[Win Shares]]>=10,"Rotation","Minimal"))) -> Rotation | X24: =IF(AND(DraftData[[#This Row],[Pick]]<=14,DraftData[[#This Row],[Win Shares]]<10),"Yes","No") -> No | Y24: =DraftData[[#This Row],[Win Shares]]/DraftData[[#This Row],[Pick]] -> 0.79130435 | Z24: =DraftData[[#This Row],[Win Shares]]-_xlfn.XLOOKUP(DraftData[[#This Row],[Pick]],'Lookup Tables'!$A$2:$A$31,'Lookup Tables'!$B$2:$B$31) -> 1.5583333
A25: 2005 | B25: 24 | C25: HOU | D25: Luther Head | E25: Illinois | F25: 348 | G25: 7797 | H25: 2842 | I25: 845 | J25: 747 | K25: 0.423 | L25: 0.388 | M25: 0.773 | N25: 14.7 | O25: 0.09 | P25: 0.1 | Q25: 4.2 | R25: 22.4 | S25: 8.2 | T25: 2.4 | U25: 2.1 | V25: =IF(DraftData[[#This Row],[Pick]]<=5,"Top 5", IF(DraftData[[#This Row],[Pick]]<=14,"Lottery", IF(DraftData[[#This Row],[Pick]]<=20,"Mid First","Late First"))) -> Late First | W25: =IF(DraftData[[#This Row],[Win Shares]]>=80,"Star", IF(DraftData[[#This Row],[Win Shares]]>=30,"Starter", IF(DraftData[[#This Row],[Win Shares]]>=10,"Rotation","Minimal"))) -> Rotation | X25: =IF(AND(DraftData[[#This Row],[Pick]]<=14,DraftData[[#This Row],[Win Shares]]<10),"Yes","No") -> No | Y25: =DraftData[[#This Row],[Win Shares]]/DraftData[[#This Row],[Pick]] -> 0.6125 | Z25: =DraftData[[#This Row],[Win Shares]]-_xlfn.XLOOKUP(DraftData[[#This Row],[Pick]],'Lookup Tables'!$A$2:$A$31,'Lookup Tables'!$B$2:$B$31) -> -9.8
A26: 2005 | B26: 25 | C26: OKC | D26: Johan Petro | F26: 473 | G26: 7262 | H26: 2202 | I26: 1836 | J26: 227 | K26: 0.462 | L26: 0.154 | M26: 0.678 | N26: 5.5 | O26: 0.037 | P26: -4.6 | Q26: -4.6 | R26: 15.4 | S26: 4.7 | T26: 3.9 | U26: 0.5 | V26: =IF(DraftData[[#This Row],[Pick]]<=5,"Top 5", IF(DraftData[[#This Row],[Pick]]<=14,"Lottery", IF(DraftData[[#This Row],[Pick]]<=20,"Mid First","Late First"))) -> Late First | W26: =IF(DraftData[[#This Row],[Win Shares]]>=80,"Star", IF(DraftData[[#This Row],[Win Shares]]>=30,"Starter", IF(DraftData[[#This Row],[Win Shares]]>=10,"Rotation","Minimal"))) -> Minimal | X26: =IF(AND(DraftData[[#This Row],[Pick]]<=14,DraftData[[#This Row],[Win Shares]]<10),"Yes","No") -> No | Y26: =DraftData[[#This Row],[Win Shares]]/DraftData[[#This Row],[Pick]] -> 0.22 | Z26: =DraftData[[#This Row],[Win Shares]]-_xlfn.XLOOKUP(DraftData[[#This Row],[Pick]],'Lookup Tables'!$A$2:$A$31,'Lookup Tables'!$B$2:$B$31) -> -7.4
A27: 2005 | B27: 26 | C27: DET | D27: Jason Maxiell | E27: Cincinnati | F27: 618 | G27: 11379 | H27: 3481 | I27: 2576 | J27: 266 | K27: 0.495 | L27: 0 | M27: 0.564 | N27: 20.3 | O27: 0.086 | P27: -2.5 | Q27: -1.4 | R27: 18.4 | S27: 5.6 | T27: 4.2 | U27: 0.4 | V27: =IF(DraftData[[#This Row],[Pick]]<=5,"Top 5", IF(DraftData[[#This Row],[Pick]]<=14,"Lottery", IF(DraftData[[#This Row],[Pick]]<=20,"Mid First","Late First"))) -> Late First | W27: =IF(DraftData[[#This Row],[Win Shares]]>=80,"Star", IF(DraftData[[#This Row],[Win Shares]]>=30,"Starter", IF(DraftData[[#This Row],[Win Shares]]>=10,"Rotation","Minimal"))) -> Rotation | X27: =IF(AND(DraftData[[#This Row],[Pick]]<=14,DraftData[[#This Row],[Win Shares]]<10),"Yes","No") -> No | Y27: =DraftData[[#This Row],[Win Shares]]/DraftData[[#This Row],[Pick]] -> 0.78076923 | Z27: =DraftData[[#This Row],[Win Shares]]-_xlfn.XLOOKUP(DraftData[[#This Row],[Pick]],'Lookup Tables'!$A$2:$A$31,'Lookup Tables'!$B$2:$B$31) -> -0.1
A28: 2005 | B28: 27 | C28: POR | D28: Linas Kleiza | E28: Missouri | F28: 409 | G28: 8185 | H28: 3561 | I28: 1470 | J28: 321 | K28: 0.435 | L28: 0.335 | M28: 0.763 | N28: 13.6 | O28: 0.08 | P28: -2.3 | Q28: -0.7 | R28: 20 | S28: 8.7 | T28: 3.6 | U28: 0.8 | V28: =IF(DraftData[[#This Row],[Pick]]<=5,"Top 5", IF(DraftData[[#This Row],[Pick]]<=14,"Lottery", IF(DraftData[[#This Row],[Pick]]<=20,"Mid First","Late First"))) -> Late First | W28: =IF(DraftData[[#This Row],[Win Shares]]>=80,"Star", IF(DraftData[[#This Row],[Win Shares]]>=30,"Starter", IF(DraftData[[#This Row],[Win Shares]]>=10,"Rotation","Minimal"))) -> Rotation | X28: =IF(AND(DraftData[[#This Row],[Pick]]<=14,DraftData[[#This Row],[Win Shares]]<10),"Yes","No") -> No | Y28: =DraftData[[#This Row],[Win Shares]]/DraftData[[#This Row],[Pick]] -> 0.5037037 | Z28: =DraftData[[#This Row],[Win Shares]]-_xlfn.XLOOKUP(DraftData[[#This Row],[Pick]],'Lookup Tables'!$A$2:$A$31,'Lookup Tables'!$B$2:$B$31) -> -7.5083333
A29: 2005 | B29: 28 | C29: SAS | D29: Ian Mahinmi | F29: 618 | G29: 10353 | H29: 3209 | I29: 2705 | J29: 357 | K29: 0.533 | L29: 0.16 | M29: 0.612 | N29: 26.1 | O29: 0.121 | P29: -2 | Q29: 0.1 | R29: 16.8 | S29: 5.2 | T29: 4.4 | U29: 0.6 | V29: =IF(DraftData[[#This Row],[Pick]]<=5,"Top 5", IF(DraftData[[#This Row],[Pick]]<=14,"Lottery", IF(DraftData[[#This Row],[Pick]]<=20,"Mid First","Late First"))) -> Late First | W29: =IF(DraftData[[#This Row],[Win Shares]]>=80,"Star", IF(DraftData[[#This Row],[Win Shares]]>=30,"Starter", IF(DraftData[[#This Row],[Win Shares]]>=10,"Rotation","Minimal"))) -> Rotation | X29: =IF(AND(DraftData[[#This Row],[Pick]]<=14,DraftData[[#This Row],[Win Shares]]<10),"Yes","No") -> No | Y29: =DraftData[[#This Row],[Win Shares]]/DraftData[[#This Row],[Pick]] -> 0.93214286 | Z29: =DraftData[[#This Row],[Win Shares]]-_xlfn.XLOOKUP(DraftData[[#This Row],[Pick]],'Lookup Tables'!$A$2:$A$31,'Lookup Tables'!$B$2:$B$31) -> 17.454545
A30: 2005 | B30: 29 | C30: MIA | D30: Wayne Simien | E30: Kansas | F30: 51 | G30: 507 | H30: 169 | I30: 99 | J30: 11 | K30: 0.469 | M30: 0.854 | N30: 0.9 | O30: 0.083 | P30: -4.4 | Q30: -0.3 | R30: 9.9 | S30: 3.3 | T30: 1.9 | U30: 0.2 | V30: =IF(DraftData[[#This Row],[Pick]]<=5,"Top 5", IF(DraftData[[#This Row],[Pick]]<=14,"Lottery", IF(DraftData[[#This Row],[Pick]]<=20,"Mid First","Late First"))) -> Late First | W30: =IF(DraftData[[#This Row],[Win Shares]]>=80,"Star", IF(DraftData[[#This Row],[Win Shares]]>=30,"Starter", IF(DraftData[[#This Row],[Win Shares]]>=10,"Rotation","Minimal"))) -> Minimal | X30: =IF(AND(DraftData[[#This Row],[Pick]]<=14,DraftData[[#This Row],[Win Shares]]<10),"Yes","No") -> No | Y30: =DraftData[[#This Row],[Win Shares]]/DraftData[[#This Row],[Pick]] -> 0.031034483 | Z30: =DraftData[[#This Row],[Win Shares]]-_xlfn.XLOOKUP(DraftData[[#This Row],[Pick]],'Lookup Tables'!$A$2:$A$31,'Lookup Tables'!$B$2:$B$31) -> -4.1666667
A31: 2005 | B31: 30 | C31: NYK | D31: David Lee | E31: Florida | F31: 829 | G31: 24293 | H31: 11232 | I31: 7320 | J31: 1825 | K31: 0.535 | L31: 0.034 | M31: 0.772 | N31: 76 | O31: 0.15 | P31: 1.1 | Q31: 19.2 | R31: 29.3 | S31: 13.5 | T31: 8.8 | U31: 2.2 | V31: =IF(DraftData[[#This Row],[Pick]]<=5,"Top 5", IF(DraftData[[#This Row],[Pick]]<=14,"Lottery", IF(DraftData[[#This Row],[Pick]]<=20,"Mid First","Late First"))) -> Late First | W31: =IF(DraftData[[#This Row],[Win Shares]]>=80,"Star", IF(DraftData[[#This Row],[Win Shares]]>=30,"Starter", IF(DraftData[[#This Row],[Win Shares]]>=10,"Rotation","Minimal"))) -> Starter | X31: =IF(AND(DraftData[[#This Row],[Pick]]<=14,DraftData[[#This Row],[Win Shares]]<10),"Yes","No") -> No | Y31: =DraftData[[#This Row],[Win Shares]]/DraftData[[#This Row],[Pick]] -> 2.5333333 | Z31: =DraftData[[#This Row],[Win Shares]]-_xlfn.XLOOKUP(DraftData[[#This Row],[Pick]],'Lookup Tables'!$A$2:$A$31,'Lookup Tables'!$B$2:$B$31) -> 55.281818
A32: 2006 | B32: 1 | C32: TOR | D32: Andrea Bargnani | F32: 550 | G32: 15806 | H32: 7873 | I32: 2541 | J32: 653 | K32: 0.439 | L32: 0.354 | M32: 0.824 | N32: 18.9 | O32: 0.057 | P32: -1.6 | Q32: 1.5 | R32: 28.7 | S32: 14.3 | T32: 4.6 | U32: 1.2 | V32: =IF(DraftData[[#This Row],[Pick]]<=5,"Top 5", IF(DraftData[[#This Row],[Pick]]<=14,"Lottery", IF(DraftData[[#This Row],[Pick]]<=20,"Mid First","Late First"))) -> Top 5 | W32: =IF(DraftData[[#This Row],[Win Shares]]>=80,"Star", IF(DraftData[[#This Row],[Win Shares]]>=30,"Starter", IF(DraftData[[#This Row],[Win Shares]]>=10,"Rotation","Minimal"))) -> Rotation | X32: =IF(AND(DraftData[[#This Row],[Pick]]<=14,DraftData[[#This Row],[Win Shares]]<10),"Yes","No") -> No | Y32: =DraftData[[#This Row],[Win Shares]]/DraftData[[#This Row],[Pick]] -> 18.9 | Z32: =DraftData[[#This Row],[Win Shares]]-_xlfn.XLOOKUP(DraftData[[#This Row],[Pick]],'Lookup Tables'!$A$2:$A$31,'Lookup Tables'!$B$2:$B$31) -> -24.683333
A33: 2006 | B33: 2 | C33: CHI | D33: LaMarcus Aldridge | E33: Texas | F33: 1068 | G33: 36086 | H33: 20488 | I33: 8702 | J33: 2067 | K33: 0.493 | L33: 0.32 | M33: 0.812 | N33: 115.3 | O33: 0.153 | P33: 1.7 | Q33: 33.3 | R33: 33.8 | S33: 19.2 | T33: 8.1 | U33: 1.9 | V33: =IF(DraftData[[#This Row],[Pick]]<=5,"Top 5", IF(DraftData[[#This Row],[Pick]]<=14,"Lottery", IF(DraftData[[#This Row],[Pick]]<=20,"Mid First","Late First"))) -> Top 5 | W33: =IF(DraftData[[#This Row],[Win Shares]]>=80,"Star", IF(DraftData[[#This Row],[Win Shares]]>=30,"Starter", IF(DraftData[[#This Row],[Win Shares]]>=10,"Rotation","Minimal"))) -> Star | X33: =IF(AND(DraftData[[#This Row],[Pick]]<=14,DraftData[[#This Row],[Win Shares]]<10),"Yes","No") -> No | Y33: =DraftData[[#This Row],[Win Shares]]/DraftData[[#This Row],[Pick]] -> 57.65 | Z33: =DraftData[[#This Row],[Win Shares]]-_xlfn.XLOOKUP(DraftData[[#This Row],[Pick]],'Lookup Tables'!$A$2:$A$31,'Lookup Tables'!$B$2:$B$31) -> 75.508333
A34: 2006 | B34: 3 | C34: CHA | D34: Adam Morrison | E34: Gonzaga | F34: 161 | G34: 3278 | H34: 1200 | I34: 342 | J34: 222 | K34: 0.373 | L34: 0.331 | M34: 0.71 | N34: -1.4 | O34: -0.021 | P34: -5 | Q34: -2.4 | R34: 20.4 | S34: 7.5 | T34: 2.1 | U34: 1.4 | V34: =IF(DraftData[[#This Row],[Pick]]<=5,"Top 5", IF(DraftData[[#This Row],[Pick]]<=14,"Lottery", IF(DraftData[[#This Row],[Pick]]<=20,"Mid First","Late First"))) -> Top 5 | W34: =IF(DraftData[[#This Row],[Win Shares]]>=80,"Star", IF(DraftData[[#This Row],[Win Shares]]>=30,"Starter", IF(DraftData[[#This Row],[Win Shares]]>=10,"Rotation","Minimal"))) -> Minimal | X34: =IF(AND(DraftData[[#This Row],[Pick]]<=14,DraftData[[#This Row],[Win Shares]]<10),"Yes","No") -> Yes | Y34: =DraftData[[#This Row],[Win Shares]]/DraftData[[#This Row],[Pick]] -> -0.46666667 | Z34: =DraftData[[#This Row],[Win Shares]]-_xlfn.XLOOKUP(DraftData[[#This Row],[Pick]],'Lookup Tables'!$A$2:$A$31,'Lookup Tables'!$B$2:$B$31) -> -52.166667
A35: 2006 | B35: 4 | C35: POR | D35: Tyrus Thomas | E35: LSU | F35: 402 | G35: 7932 | H35: 3093 | I35: 1938 | J35: 347 | K35: 0.438 | L35: 0.235 | M35: 0.732 | N35: 13 | O35: 0.078 | P35: -1.2 | Q35: 1.7 | R35: 19.7 | S35: 7.7 | T35: 4.8 | U35: 0.9 | V35: =IF(DraftData[[#This Row],[Pick]]<=5,"Top 5", IF(DraftData[[#This Row],[Pick]]<=14,"Lottery", IF(DraftData[[#This Row],[Pick]]<=20,"Mid First","Late First"))) -> Top 5 | W35: =IF(DraftData[[#This Row],[Win Shares]]>=80,"Star", IF(DraftData[[#This Row],[Win Shares]]>=30,"Starter", IF(DraftData[[#This Row],[Win Shares]]>=10,"Rotation","Minimal"))) -> Rotation | X35: =IF(AND(DraftData[[#This Row],[Pick]]<=14,DraftData[[#This Row],[Win Shares]]<10),"Yes","No") -> No | Y35: =DraftData[[#This Row],[Win Shares]]/DraftData[[#This Row],[Pick]] -> 3.25 | Z35: =DraftData[[#This Row],[Win Shares]]-_xlfn.XLOOKUP(DraftData[[#This Row],[Pick]],'Lookup Tables'!$A$2:$A$31,'Lookup Tables'!$B$2:$B$31) -> -35.558333
A36: 2006 | B36: 5 | C36: ATL | D36: Shelden Williams | E36: Duke | F36: 361 | G36: 5586 | H36: 1618 | I36: 1562 | J36: 163 | K36: 0.462 | L36: 0.222 | M36: 0.74 | N36: 9.9 | O36: 0.085 | P36: -3 | Q36: -1.5 | R36: 15.5 | S36: 4.5 | T36: 4.3 | U36: 0.5 | V36: =IF(DraftData[[#This Row],[Pick]]<=5,"Top 5", IF(DraftData[[#This Row],[Pick]]<=14,"Lottery", IF(DraftData[[#This Row],[Pick]]<=20,"Mid First","Late First"))) -> Top 5 | W36: =IF(DraftData[[#This Row],[Win Shares]]>=80,"Star", IF(DraftData[[#This Row],[Win Shares]]>=30,"Starter", IF(DraftData[[#This Row],[Win Shares]]>=10,"Rotation","Minimal"))) -> Minimal | X36: =IF(AND(DraftData[[#This Row],[Pick]]<=14,DraftData[[#This Row],[Win Shares]]<10),"Yes","No") -> Yes | Y36: =DraftData[[#This Row],[Win Shares]]/DraftData[[#This Row],[Pick]] -> 1.98 | Z36: =DraftData[[#This Row],[Win Shares]]-_xlfn.XLOOKUP(DraftData[[#This Row],[Pick]],'Lookup Tables'!$A$2:$A$31,'Lookup Tables'!$B$2:$B$31) -> -21.458333
A37: 2006 | B37: 6 | C37: MIN | D37: Brandon Roy | E37: Washington | F37: 326 | G37: 11561 | H37: 6136 | I37: 1388 | J37: 1517 | K37: 0.459 | L37: 0.348 | M37: 0.8 | N37: 37.4 | O37: 0.155 | P37: 3.6 | Q37: 16.3 | R37: 35.5 | S37: 18.8 | T37: 4.3 | U37: 4.7 | V37: =IF(DraftData[[#This Row],[Pick]]<=5,"Top 5", IF(DraftData[[#This Row],[Pick]]<=14,"Lottery", IF(DraftData[[#This Row],[Pick]]<=20,"Mid First","Late First"))) -> Lottery | W37: =IF(DraftData[[#This Row],[Win Shares]]>=80,"Star", IF(DraftData[[#This Row],[Win Shares]]>=30,"Starter", IF(DraftData[[#This Row],[Win Shares]]>=10,"Rotation","Minimal"))) -> Starter | X37: =IF(AND(DraftData[[#This Row],[Pick]]<=14,DraftData[[#This Row],[Win Shares]]<10),"Yes","No") -> No | Y37: =DraftData[[#This Row],[Win Shares]]/DraftData[[#This Row],[Pick]] -> 6.2333333 | Z37: =DraftData[[#This Row],[Win Shares]]-_xlfn.XLOOKUP(DraftData[[#This Row],[Pick]],'Lookup Tables'!$A$2:$A$31,'Lookup Tables'!$B$2:$B$31) -> 9.7416667
A38: 2006 | B38: 7 | C38: BOS | D38: Randy Foye | E38: Villanova | F38: 752 | G38: 19279 | H38: 7729 | I38: 1686 | J38: 2112 | K38: 0.401 | L38: 0.366 | M38: 0.852 | N38: 23.5 | O38: 0.058 | P38: -1.2 | Q38: 3.8 | R38: 25.6 | S38: 10.3 | T38: 2.2 | U38: 2.8 | V38: =IF(DraftData[[#This Row],[Pick]]<=5,"Top 5", IF(DraftData[[#This Row],[Pick]]<=14,"Lottery", IF(DraftData[[#This Row],[Pick]]<=20,"Mid First","Late First"))) -> Lottery | W38: =IF(DraftData[[#This Row],[Win Shares]]>=80,"Star", IF(DraftData[[#This Row],[Win Shares]]>=30,"Starter", IF(DraftData[[#This Row],[Win Shares]]>=10,"Rotation","Minimal"))) -> Rotation | X38: =IF(AND(DraftData[[#This Row],[Pick]]<=14,DraftData[[#This Row],[Win Shares]]<10),"Yes","No") -> No | Y38: =DraftData[[#This Row],[Win Shares]]/DraftData[[#This Row],[Pick]] -> 3.3571429 | Z38: =DraftData[[#This Row],[Win Shares]]-_xlfn.XLOOKUP(DraftData[[#This Row],[Pick]],'Lookup Tables'!$A$2:$A$31,'Lookup Tables'!$B$2:$B$31) -> -10.475
A39: 2006 | B39: 8 | C39: HOU | D39: Rudy Gay | E39: UConn | F39: 1044 | G39: 33406 | H39: 17215 | I39: 6040 | J39: 2206 | K39: 0.453 | L39: 0.349 | M39: 0.799 | N39: 60.3 | O39: 0.087 | P39: 0.7 | Q39: 22.9 | R39: 32 | S39: 16.5 | T39: 5.8 | U39: 2.1 | V39: =IF(DraftData[[#This Row],[Pick]]<=5,"Top 5", IF(DraftData[[#This Row],[Pick]]<=14,"Lottery", IF(DraftData[[#This Row],[Pick]]<=20,"Mid First","Late First"))) -> Lottery | W39: =IF(DraftData[[#This Row],[Win Shares]]>=80,"Star", IF(DraftData[[#This Row],[Win Shares]]>=30,"Starter", IF(DraftData[[#This Row],[Win Shares]]>=10,"Rotation","Minimal"))) -> Starter | X39: =IF(AND(DraftData[[#This Row],[Pick]]<=14,DraftData[[#This Row],[Win Shares]]<10),"Yes","No") -> No | Y39: =DraftData[[#This Row],[Win Shares]]/DraftData[[#This Row],[Pick]] -> 7.5375 | Z39: =DraftData[[#This Row],[Win Shares]]-_xlfn.XLOOKUP(DraftData[[#This Row],[Pick]],'Lookup Tables'!$A$2:$A$31,'Lookup Tables'!$B$2:$B$31) -> 39.141667
A40: 2006 | B40: 9 | C40: GSW | D40: Patrick O'Bryant | E40: Bradley | F40: 90 | G40: 524 | H40: 186 | I40: 127 | J40: 25 | K40: 0.494 | L40: 0 | M40: 0.583 | N40: 0.5 | O40: 0.046 | P40: -4.6 | Q40: -0.3 | R40: 5.8 | S40: 2.1 | T40: 1.4 | U40: 0.3 | V40: =IF(DraftData[[#This Row],[Pick]]<=5,"Top 5", IF(DraftData[[#This Row],[Pick]]<=14,"Lottery", IF(DraftData[[#This Row],[Pick]]<=20,"Mid First","Late First"))) -> Lottery | W40: =IF(DraftData[[#This Row],[Win Shares]]>=80,"Star", IF(DraftData[[#This Row],[Win Shares]]>=30,"Starter", IF(DraftData[[#This Row],[Win Shares]]>=10,"Rotation","Minimal"))) -> Minimal | X40: =IF(AND(DraftData[[#This Row],[Pick]]<=14,DraftData[[#This Row],[Win Shares]]<10),"Yes","No") -> Yes | Y40: =DraftData[[#This Row],[Win Shares]]/DraftData[[#This Row],[Pick]] -> 0.055555556 | Z40: =DraftData[[#This Row],[Win Shares]]-_xlfn.XLOOKUP(DraftData[[#This Row],[Pick]],'Lookup Tables'!$A$2:$A$31,'Lookup Tables'!$B$2:$B$31) -> -36.891667
...

Sheet Methodology
A1: Dataset: First-round NBA draft picks from 2005–2016. Career statistics reflect player performance through the conclusion of the 2021–22 NBA season. The study focuses on draft classes through 2016 so that each player had at least six NBA seasons to develop by the end of the observation period.

Sheet Pivot Tables
A2: Pick Range | B2: Average Win Shares
A3: Late First | B3: 16.904274
A4: Lottery | B4: 25.036449
A5: Mid First | B5: 17.559722
A6: Top 5 | B6: 42.811667
A7: Grand Total | B7: 23.847472
A9: Pick Range | B9: Average Games
A10: Late First | B10: 353.17094
A11: Lottery | B11: 485.15888
A12: Mid First | B12: 397.31944
A13: Top 5 | B13: 569.36667
A14: Grand Total | B14: 438.20787
A16: Pick Range | B16: Average BPM
A17: Late First | B17: -1.7504274
A18: Lottery | B18: -0.82149533
A19: Mid First | B19: -1.7222222
A20: Top 5 | B20: 0.43666667
A21: Grand Total | B21: -1.0969101
A23: Count of Bust? | B23: Bust?
A24: Pick Range | B24: No | C24: Yes | D24: Grand Total
A25: Late First | B25: 120 | D25: 120
A26: Lottery | B26: 72 | C26: 36 | D26: 108
A27: Mid First | B27: 72 | D27: 72
A28: Top 5 | B28: 48 | C28: 12 | D28: 60
A29: Grand Total | B29: 312 | C29: 48 | D29: 360
A31: Career Tier | B31: Count of Player
A32: Minimal | B32: 147
A33: Rotation | B33: 116
A34: Star | B34: 17
A35: Starter | B35: 80
A36: Grand Total | B36: 360
A38: Pick | B38: Average Win Shares
A39: 1 | B39: 43.583333
A40: 2 | B40: 39.791667
A41: 3 | B41: 50.766667
A42: 4 | B42: 48.558333
A43: 5 | B43: 31.358333
A44: 6 | B44: 27.658333
A45: 7 | B45: 33.975
A46: 8 | B46: 21.158333
...

Sheet Charts

Sheet Lookup Tables
A1: Pick | B1: Average Win Shares
A2: 1 | B2: 43.583333
A3: 2 | B3: 39.791667
A4: 3 | B4: 50.766667
A5: 4 | B5: 48.558333
A6: 5 | B6: 31.358333
A7: 6 | B7: 27.658333
A8: 7 | B8: 33.975
A9: 8 | B9: 21.158333
A10: 9 | B10: 37.391667
A11: 10 | B11: 26.85
A12: 11 | B12: 22.7
A13: 12 | B13: 21.316667
... A31: 30 | B31: 20.718182
A32: Grand Total | B32: 23.847472
